Traceback (most recent call last):
  File "/Users/patrickwalls/anaconda3/envs/jb/lib/python3.10/site-packages/jupyter_cache/executors/utils.py", line 58, in single_nb_execution
    executenb(
  File "/Users/patrickwalls/anaconda3/envs/jb/lib/python3.10/site-packages/nbclient/client.py", line 1305, in execute
    return NotebookClient(nb=nb, resources=resources, km=km, **kwargs).execute()
  File "/Users/patrickwalls/anaconda3/envs/jb/lib/python3.10/site-packages/jupyter_core/utils/__init__.py", line 166, in wrapped
    return loop.run_until_complete(inner)
  File "/Users/patrickwalls/anaconda3/envs/jb/lib/python3.10/asyncio/base_events.py", line 649, in run_until_complete
    return future.result()
  File "/Users/patrickwalls/anaconda3/envs/jb/lib/python3.10/site-packages/nbclient/client.py", line 705, in async_execute
    await self.async_execute_cell(
  File "/Users/patrickwalls/anaconda3/envs/jb/lib/python3.10/site-packages/nbclient/client.py", line 1058, in async_execute_cell
    await self._check_raise_for_error(cell, cell_index, exec_reply)
  File "/Users/patrickwalls/anaconda3/envs/jb/lib/python3.10/site-packages/nbclient/client.py", line 914, in _check_raise_for_error
    raise CellExecutionError.from_cell_and_msg(cell, exec_reply_content)
nbclient.exceptions.CellExecutionError: An error occurred while executing the following cell:
------------------
plt.scatter(X[:,0],X[:,1],c=y)
plt.xlabel(data.feature_names[0])
plt.ylabel(data.feature_names[1])
plt.grid(True), plt.colorbar()
plt.show()
------------------


[0;31m---------------------------------------------------------------------------[0m
[0;31mNameError[0m                                 Traceback (most recent call last)
Cell [0;32mIn[17], line 2[0m
[1;32m      1[0m plt[38;5;241m.[39mscatter(X[:,[38;5;241m0[39m],X[:,[38;5;241m1[39m],c[38;5;241m=[39my)
[0;32m----> 2[0m plt[38;5;241m.[39mxlabel([43mdata[49m[38;5;241m.[39mfeature_names[[38;5;241m0[39m])
[1;32m      3[0m plt[38;5;241m.[39mylabel(data[38;5;241m.[39mfeature_names[[38;5;241m1[39m])
[1;32m      4[0m plt[38;5;241m.[39mgrid([38;5;28;01mTrue[39;00m), plt[38;5;241m.[39mcolorbar()

[0;31mNameError[0m: name 'data' is not defined

